sqlalchemy.exc.ProgrammingError: This app has encountered an error. The original error message is redacted to prevent data leaks. Full error details have been recorded in the logs (if you're on Streamlit Cloud, click on 'Manage app' in the lower right of your app).
Traceback:
File "/home/runner/workspace/.pythonlibs/lib/python3.11/site-packages/streamlit/runtime/scriptrunner/exec_code.py", line 128, in exec_func_with_error_handling
    result = func()
             ^^^^^^
File "/home/runner/workspace/.pythonlibs/lib/python3.11/site-packages/streamlit/runtime/scriptrunner/script_runner.py", line 667, in code_to_exec
    _mpa_v1(self._main_script_path)
File "/home/runner/workspace/.pythonlibs/lib/python3.11/site-packages/streamlit/runtime/scriptrunner/script_runner.py", line 165, in _mpa_v1
    page.run()
File "/home/runner/workspace/.pythonlibs/lib/python3.11/site-packages/streamlit/navigation/page.py", line 300, in run
    exec(code, module.__dict__)  # noqa: S102
    ^^^^^^^^^^^^^^^^^^^^^^^^^^^
File "/home/runner/workspace/pages/1_üöó_–ê–≤—Ç–æ–º–æ–±–∏–ª–∏.py", line 1511, in <module>
    show_vehicle_assignments()
File "/home/runner/workspace/pages/1_üöó_–ê–≤—Ç–æ–º–æ–±–∏–ª–∏.py", line 1211, in show_vehicle_assignments
    show_add_assignment_form()
File "/home/runner/workspace/pages/1_üöó_–ê–≤—Ç–æ–º–æ–±–∏–ª–∏.py", line 1352, in show_add_assignment_form
    drivers = execute_query("""
              ^^^^^^^^^^^^^^^^^
File "/home/runner/workspace/database.py", line 51, in execute_query
    raise e
File "/home/runner/workspace/database.py", line 33, in execute_query
    result = connection.execute(text(query), params)
             ^^^^^^^^^^^^^^^^^^^^^^^^^^^^^^^^^^^^^^^
File "/home/runner/workspace/.pythonlibs/lib/python3.11/site-packages/sqlalchemy/engine/base.py", line 1419, in execute
    return meth(
           ^^^^^
File "/home/runner/workspace/.pythonlibs/lib/python3.11/site-packages/sqlalchemy/sql/elements.py", line 526, in _execute_on_connection
    return connection._execute_clauseelement(
           ^^^^^^^^^^^^^^^^^^^^^^^^^^^^^^^^^^
File "/home/runner/workspace/.pythonlibs/lib/python3.11/site-packages/sqlalchemy/engine/base.py", line 1641, in _execute_clauseelement
    ret = self._execute_context(
          ^^^^^^^^^^^^^^^^^^^^^^
File "/home/runner/workspace/.pythonlibs/lib/python3.11/site-packages/sqlalchemy/engine/base.py", line 1846, in _execute_context
    return self._exec_single_context(
           ^^^^^^^^^^^^^^^^^^^^^^^^^^
File "/home/runner/workspace/.pythonlibs/lib/python3.11/site-packages/sqlalchemy/engine/base.py", line 1986, in _exec_single_context
    self._handle_dbapi_exception(
File "/home/runner/workspace/.pythonlibs/lib/python3.11/site-packages/sqlalchemy/engine/base.py", line 2355, in _handle_dbapi_exception
    raise sqlalchemy_exception.with_traceback(exc_info[2]) from e
File "/home/runner/workspace/.pythonlibs/lib/python3.11/site-packages/sqlalchemy/engine/base.py", line 1967, in _exec_single_context
    self.dialect.do_execute(
File "/home/runner/workspace/.pythonlibs/lib/python3.11/site-packages/sqlalchemy/engine/default.py", line 951, in do_execute
    cursor.execute(statement, parameters)